{"level":"INFO","message":"Logging to file: a_sus_logs/app_20250614_224239.log.jsonl","timestamp":"2025-06-15T01:42:39.318138+00:00","logger":"test_exceptions","module":"logger","function":"setup_logging","line":362,"thread_name":"MainThread"}
{"level":"ERROR","message":"Caught an exception while dividing\nTraceback (most recent call last):\n  File \"/Users/wrath/projects/arrow-sus/test_logger.py\", line 89, in test_exception_logging\n    result = 10 / 0\n             ~~~^~~\nZeroDivisionError: division by zero","timestamp":"2025-06-15T01:42:39.318164+00:00","logger":"test_exceptions","module":"test_logger","function":"test_exception_logging","line":91,"thread_name":"MainThread"}
{"level":"ERROR","message":"This is using logger.exception() method\nTraceback (most recent call last):\n  File \"/Users/wrath/projects/arrow-sus/test_logger.py\", line 89, in test_exception_logging\n    result = 10 / 0\n             ~~~^~~\nZeroDivisionError: division by zero","timestamp":"2025-06-15T01:42:39.318508+00:00","logger":"test_exceptions","module":"test_logger","function":"test_exception_logging","line":92,"thread_name":"MainThread"}
{"level":"WARNING","message":"Key error occurred: 'nonexistent_key'\nTraceback (most recent call last):\n  File \"/Users/wrath/projects/arrow-sus/test_logger.py\", line 97, in test_exception_logging\n    value = my_dict[\"nonexistent_key\"]\n            ~~~~~~~^^^^^^^^^^^^^^^^^^^\nKeyError: 'nonexistent_key'","timestamp":"2025-06-15T01:42:39.318598+00:00","logger":"test_exceptions","module":"test_logger","function":"test_exception_logging","line":99,"thread_name":"MainThread"}
{"level":"INFO","message":"Logging to file: a_sus_logs/app_20250614_224239.log.jsonl","timestamp":"2025-06-15T01:42:39.320364+00:00","logger":"test_custom","module":"logger","function":"setup_logging","line":362,"thread_name":"MainThread"}
{"level":"INFO","message":"User action performed","timestamp":"2025-06-15T01:42:39.320384+00:00","logger":"test_custom","module":"test_logger","function":"test_custom_fields","line":111,"thread_name":"MainThread","user_id":"user123","action":"login","ip_address":"192.168.1.100","session_id":"sess_abc123"}
{"level":"ERROR","message":"Database connection failed","timestamp":"2025-06-15T01:42:39.320397+00:00","logger":"test_custom","module":"test_logger","function":"test_custom_fields","line":121,"thread_name":"MainThread","database":"postgres","host":"db.example.com","port":5432,"retry_count":3}
